# 异步

## 回调

回调问题：（你将要不得不为每一个传递到你不能信任的工具中的回调 都创造一大堆的特殊逻辑，缺乏顺序性和缺乏可靠性）

- 调用回调过早（在它开始追踪之前）
- 调用回调过晚 (或不调)
- 调用回调太少或太多次（就像你遇到的问题！）
- 没能向你的回调传递必要的环境/参数
- 吞掉了可能发生的错误/异常

错误优先风格

```javascript
function timeoutify(fn, delay) {
  let timer = setTimeout(function() {
    timer = null;
    fn(new Error("Timeout"));
  }, delay);

  return function() {
    if (timer) {
      clearTimeout(timer);
      fn.apply(this, [null].concat([].slice.call(arguments)));
    }
  };
}

// 使用“错误优先”风格的回调设计
function foo(err, data) {
  if (err) {
    console.error(err);
  } else {
    console.log(data);
  }
}

ajax("http://some.url.1", timeoutify(foo, 500));
```

## 事件监听

## promise

thenable

```javascript
if (
  p !== null &&
  (typeof p === "object" || typeof p === "function") &&
  typeof p.then === "function"
) {
  // 认为它是一个thenable!
} else {
  // 不是一个thenable
}
```

### 调的太早

一个任务有时会同步完地成，而有时会异步地完成，这将导致竞合状态。当你在 Promise 上调用 then(..)的时候，即便这个 Promise 已经被解析了，你给 then(..)提供的回调也将 总是 被异步地调用，不必再插入你自己的 setTimeout(..,0)黑科技了。Promise 自动地防止了 Zalgo 效应。

### 调的太晚

在 resolve(..)或 reject(..)被 Promise 创建机制调用时，一个 Promise 的 then(..)上注册的监听回调将自动地被排程。这些被排程好的回调将在下一个异步时刻被可预测地触发。

同步监听是不可能的，所以不可能有一个同步的任务链的运行来“推迟”另一个回调的发生。也就是说，当一个 Promise 被解析时，所有在 then(..)上注册的回调都将被立即，按顺序地，在下一个异步机会时被调用，而且没有任何在这些回调中发生的事情可以影响/推迟其他回调的调用。

```javascript
p.then(function() {
  p.then(function() {
    console.log("C");
  });
  console.log("A");
});
p.then(function() {
  console.log("B");
});
// A B C
```

这里，有赖于 Promise 如何定义操作，"C"不可能干扰并优先于"B"。

### 根本不调回调

如果 Promise 本身不管怎样永远没有被解析呢？使用一个称为“竞赛（race）”的高级抽象

```javascript
// 一个使Promise超时的工具
function timeoutPromise(delay) {
  return new Promise(function(resolve, reject) {
    setTimeout(function() {
      reject("Timeout!");
    }, delay);
  });
}

// 为`foo()`设置一个超时
Promise.race([
  foo(), // 尝试调用`foo()`
  timeoutPromise(3000) // 给它3秒钟
]).then(
  function() {
    // `foo(..)`及时地完成了！
  },
  function(err) {
    // `foo()`不是被拒绝了，就是它没有及时完成
    // 那么可以考察`err`来知道是哪种情况
  }
);
```

### 调太少或太多次

根据定义，对于被调用的回调来讲 一次 是一个合适的次数。“太少”的情况将会是 0 次，和我们刚刚考察的从不调用是相同的。

“太多”的情况则很容易解释。Promise 被定义为只能被解析一次。如果因为某些原因，Promise 的创建代码试着调用 resolve(..)或 reject(..)许多次，或者试着同时调用它们俩，Promise 将仅接受第一次解析，而无声地忽略后续的尝试。

因为一个 Promise 仅能被解析一次，所以任何 then(..)上注册的（每个）回调将仅仅被调用一次。

当然，如果你把同一个回调注册多次（比如 p.then(f); p.then(f);），那么它就会被调用注册的那么多次。响应函数仅被调用一次的保证并不能防止你砸自己的脚。

### 没能传入任何参数/环境

Promise 可以拥有最多一个解析值（完成或拒绝）。
如果无论怎样你没有用一个值明确地解析它，它的值就是 undefined，就像 JS 中常见的那样。但不管是什么值，它总是会被传入所有被注册的（并且适当地：完成或拒绝）回调中，不管是 现在 还是将来。
如果你使用多个参数调用 resolve(..)或 reject(..)，所有第一个参数之外的后续参数都会被无声地忽略。
如果你想传递多个值，你必须将它们包装在另一个单独的值中，比如一个 array 或一个 object。

### 吞掉所有错误/异常

如果在 Promise 的创建过程中的任意一点，或者在监听它的解析的过程中，一个 JS 异常错误发生的话，比如 TypeError 或 ReferenceError，这个异常将会被捕获，并且强制当前的 Promise 变为拒绝。

```javascript
var p = new Promise(function(resolve, reject) {
  foo.bar(); // `foo`没有定义，所以这是一个错误！
  resolve(42); // 永远不会跑到这里 :(
});

p.then(
  function fulfilled() {
    // 永远不会跑到这里 :(
  },
  function rejected(err) {
    // `err`将是一个来自`foo.bar()`那一行的`TypeError`异常对象
  }
);
```

但是如果 Promise 完成了，但是在监听过程中（在一个 then(..)上注册的回调上）出现了 JS 异常错误会怎样呢？即便是那些也不会丢失，但你可能会发现处理它们的方式有些令人诧异，除非你深挖一些：

```javascript
var p = new Promise(function(resolve, reject) {
  resolve(42);
});

p.then(
  function fulfilled(msg) {
    foo.bar();
    console.log(msg); // 永远不会跑到这里 :(
  },
  function rejected(err) {
    // 也永远不会跑到这里 :(
  }
);
```

p.then(..)调用本身返回另一个 promise，是 那个 promise 将会被 TypeError 异常拒绝。
为什么它不能调用我们在这里定义的错误处理器呢？表面上看起来是一个符合逻辑的行为。但它会违反 Promise 一旦被解析就 不可变 的基本原则。p 已经完成为值 42，所以它不能因为在监听 p 的解析时发生了错误，而在稍后变成一个拒绝。

除了违反原则，这样的行为还可能造成破坏，假如说有多个在 promisep 上注册的 then(..)回调，因为有些会被调用而有些不会，而且至于为什么是很明显的。

### 可信的 Promise？

为了基于 Promise 模式建立信任，还有最后一个细节需要考察。

无疑你已经注意到了，Promise 根本没有摆脱回调。它们只是改变了回调传递的位置。与将一个回调传入 foo(..)相反，我们从 foo(..)那里拿回 某些东西 （表面上是一个纯粹的 Promise），然后我们将回调传入这个 东西。

但为什么这要比仅使用回调的方式更可靠呢？我们如何确信我们拿回来的 某些东西 事实上是一个可信的 Promise？这难道不是说我们相信它仅仅因为我们已经相信它了吗？

一个 Promise 经常被忽视，但是最重要的细节之一，就是它也为这个问题给出了解决方案。包含在原生的 ES6Promise 实现中，它就是 Promise.resolve(..)。

如果你传递一个立即的，非 Promise 的，非 thenable 的值给 Promise.resolve(..)，你会得到一个用这个值完成的 promise。换句话说，下面两个 promisep1 和 p2 的行为基本上完全相同：

```javascript
var p1 = new Promise(function(resolve, reject) {
  resolve(42);
});

var p2 = Promise.resolve(42);
```

但如果你传递一个纯粹的 Promise 给 Promise.resolve(..)，你会得到这个完全相同的 promise：

```javascript
var p1 = Promise.resolve(42);

var p2 = Promise.resolve(p1);

p1 === p2; // true
```

那么我们假定，我们在调用一个 foo(..)工具，而且不能确定我们能相信它的返回值是一个行为规范的 Promise，但我们知道它至少是一个 thenable。Promise.resolve(..)将会给我们一个可靠的 Promise 包装器来进行链式调用：

```javascript
// 不要只是这么做：
foo(42).then(function(v) {
  console.log(v);
});

// 相反，这样做：
Promise.resolve(foo(42)).then(function(v) {
  console.log(v);
});
```

### 链式流程

Promise 的两个固有行为：

- 每次你在一个 Promise 上调用 then(..)的时候，它都创建并返回一个新的 Promise，我们可以在它上面进行 链接。
- 无论你从 then(..)调用的完成回调中（第一个参数）返回什么值，它都做为被链接的 Promise 的完成。

## generator + promise

## async 与 await
